<?xml version="1.0" encoding="UTF-8"?>
<!-- Generated by org.testng.reporters.JUnitReportReporter -->
<testsuite skipped="1" hostname="swathi-PC" name="jan23.WebdriverCross" tests="5" failures="0" timestamp="23 Jan 2020 18:43:53 GMT" time="29.510" errors="3">
  <testcase name="verifyLogin" time="6.693" classname="jan23.WebdriverCross"/>
  <testcase name="setup" time="22.812" classname="jan23.WebdriverCross">
    <error type="org.openqa.selenium.WebDriverException" message="java.net.ConnectException: Failed to connect to localhost/0:0:0:0:0:0:0:1:2637
Build info: version: &#039;3.14.0&#039;, revision: &#039;aacccce0&#039;, time: &#039;2018-08-02T20:19:58.91Z&#039;
System info: host: &#039;SWATHI-PC&#039;, ip: &#039;10.9.50.23&#039;, os.name: &#039;Windows 7&#039;, os.arch: &#039;x86&#039;, os.version: &#039;6.1&#039;, java.version: &#039;1.8.0_202&#039;
Driver info: driver.version: FirefoxDriver">
      <![CDATA[org.openqa.selenium.WebDriverException: java.net.ConnectException: Failed to connect to localhost/0:0:0:0:0:0:0:1:2637
Build info: version: '3.14.0', revision: 'aacccce0', time: '2018-08-02T20:19:58.91Z'
System info: host: 'SWATHI-PC', ip: '10.9.50.23', os.name: 'Windows 7', os.arch: 'x86', os.version: '6.1', java.version: '1.8.0_202'
Driver info: driver.version: FirefoxDriver
at org.openqa.selenium.remote.service.DriverCommandExecutor.execute(DriverCommandExecutor.java:92)
at org.openqa.selenium.remote.RemoteWebDriver.execute(RemoteWebDriver.java:548)
at org.openqa.selenium.remote.RemoteWebDriver.startSession(RemoteWebDriver.java:212)
at org.openqa.selenium.remote.RemoteWebDriver.<init>(RemoteWebDriver.java:130)
at org.openqa.selenium.firefox.FirefoxDriver.<init>(FirefoxDriver.java:125)
at org.openqa.selenium.firefox.FirefoxDriver.<init>(FirefoxDriver.java:103)
at jan23.WebdriverCross.setup(WebdriverCross.java:33)
at sun.reflect.NativeMethodAccessorImpl.invoke0(Native Method)
at sun.reflect.NativeMethodAccessorImpl.invoke(Unknown Source)
at sun.reflect.DelegatingMethodAccessorImpl.invoke(Unknown Source)
at java.lang.reflect.Method.invoke(Unknown Source)
at org.testng.internal.MethodInvocationHelper.invokeMethod(MethodInvocationHelper.java:124)
at org.testng.internal.MethodInvocationHelper.invokeMethodConsideringTimeout(MethodInvocationHelper.java:59)
at org.testng.internal.Invoker.invokeConfigurationMethod(Invoker.java:455)
at org.testng.internal.Invoker.invokeConfigurations(Invoker.java:222)
at org.testng.internal.Invoker.invokeConfigurations(Invoker.java:142)
at org.testng.TestRunner.beforeRun(TestRunner.java:529)
at org.testng.TestRunner.run(TestRunner.java:497)
at org.testng.SuiteRunner.runTest(SuiteRunner.java:455)
at org.testng.SuiteRunner.runSequentially(SuiteRunner.java:450)
at org.testng.SuiteRunner.privateRun(SuiteRunner.java:415)
at org.testng.SuiteRunner.run(SuiteRunner.java:364)
at org.testng.SuiteRunnerWorker.runSuite(SuiteRunnerWorker.java:52)
at org.testng.SuiteRunnerWorker.run(SuiteRunnerWorker.java:84)
at org.testng.TestNG.runSuitesSequentially(TestNG.java:1208)
at org.testng.TestNG.runSuitesLocally(TestNG.java:1137)
at org.testng.TestNG.runSuites(TestNG.java:1049)
at org.testng.TestNG.run(TestNG.java:1017)
at org.testng.remote.AbstractRemoteTestNG.run(AbstractRemoteTestNG.java:114)
at org.testng.remote.RemoteTestNG.initAndRun(RemoteTestNG.java:251)
at org.testng.remote.RemoteTestNG.main(RemoteTestNG.java:77)
Caused by: java.net.ConnectException: Failed to connect to localhost/0:0:0:0:0:0:0:1:2637
at okhttp3.internal.connection.RealConnection.connectSocket(RealConnection.java:242)
at okhttp3.internal.connection.RealConnection.connect(RealConnection.java:160)
at okhttp3.internal.connection.StreamAllocation.findConnection(StreamAllocation.java:257)
at okhttp3.internal.connection.StreamAllocation.findHealthyConnection(StreamAllocation.java:135)
at okhttp3.internal.connection.StreamAllocation.newStream(StreamAllocation.java:114)
at okhttp3.internal.connection.ConnectInterceptor.intercept(ConnectInterceptor.java:42)
at okhttp3.internal.http.RealInterceptorChain.proceed(RealInterceptorChain.java:147)
at okhttp3.internal.http.RealInterceptorChain.proceed(RealInterceptorChain.java:121)
at okhttp3.internal.cache.CacheInterceptor.intercept(CacheInterceptor.java:93)
at okhttp3.internal.http.RealInterceptorChain.proceed(RealInterceptorChain.java:147)
at okhttp3.internal.http.RealInterceptorChain.proceed(RealInterceptorChain.java:121)
at okhttp3.internal.http.BridgeInterceptor.intercept(BridgeInterceptor.java:93)
at okhttp3.internal.http.RealInterceptorChain.proceed(RealInterceptorChain.java:147)
at okhttp3.internal.http.RetryAndFollowUpInterceptor.intercept(RetryAndFollowUpInterceptor.java:126)
at okhttp3.internal.http.RealInterceptorChain.proceed(RealInterceptorChain.java:147)
at okhttp3.internal.http.RealInterceptorChain.proceed(RealInterceptorChain.java:121)
at okhttp3.RealCall.getResponseWithInterceptorChain(RealCall.java:200)
at okhttp3.RealCall.execute(RealCall.java:77)
at org.openqa.selenium.remote.internal.OkHttpClient.execute(OkHttpClient.java:105)
at org.openqa.selenium.remote.ProtocolHandshake.createSession(ProtocolHandshake.java:101)
at org.openqa.selenium.remote.ProtocolHandshake.createSession(ProtocolHandshake.java:73)
at org.openqa.selenium.remote.HttpCommandExecutor.execute(HttpCommandExecutor.java:136)
at org.openqa.selenium.remote.service.DriverCommandExecutor.execute(DriverCommandExecutor.java:83)
... 30 more
Caused by: java.net.ConnectException: Connection refused: connect
at java.net.DualStackPlainSocketImpl.waitForConnect(Native Method)
at java.net.DualStackPlainSocketImpl.socketConnect(Unknown Source)
at java.net.AbstractPlainSocketImpl.doConnect(Unknown Source)
at java.net.AbstractPlainSocketImpl.connectToAddress(Unknown Source)
at java.net.AbstractPlainSocketImpl.connect(Unknown Source)
at java.net.PlainSocketImpl.connect(Unknown Source)
at java.net.SocksSocketImpl.connect(Unknown Source)
at java.net.Socket.connect(Unknown Source)
at okhttp3.internal.platform.Platform.connectSocket(Platform.java:129)
at okhttp3.internal.connection.RealConnection.connectSocket(RealConnection.java:240)
... 52 more
]]>
    </error>
  </testcase> <!-- setup -->
  <testcase name="verifyLogin" time="0.000" classname="jan23.WebdriverCross">
    <skipped/>
  </testcase> <!-- verifyLogin -->
  <testcase name="verifyLogin" time="0.002" classname="jan23.WebdriverCross">
    <error type="java.lang.NullPointerException">
      <![CDATA[java.lang.NullPointerException
at jan23.WebdriverCross.verifyLogin(WebdriverCross.java:45)
at sun.reflect.NativeMethodAccessorImpl.invoke0(Native Method)
at sun.reflect.NativeMethodAccessorImpl.invoke(Unknown Source)
at sun.reflect.DelegatingMethodAccessorImpl.invoke(Unknown Source)
at java.lang.reflect.Method.invoke(Unknown Source)
at org.testng.internal.MethodInvocationHelper.invokeMethod(MethodInvocationHelper.java:124)
at org.testng.internal.Invoker.invokeMethod(Invoker.java:580)
at org.testng.internal.Invoker.invokeTestMethod(Invoker.java:716)
at org.testng.internal.Invoker.invokeTestMethods(Invoker.java:988)
at org.testng.internal.TestMethodWorker.invokeTestMethods(TestMethodWorker.java:125)
at org.testng.internal.TestMethodWorker.run(TestMethodWorker.java:109)
at org.testng.TestRunner.privateRun(TestRunner.java:648)
at org.testng.TestRunner.run(TestRunner.java:505)
at org.testng.SuiteRunner.runTest(SuiteRunner.java:455)
at org.testng.SuiteRunner.runSequentially(SuiteRunner.java:450)
at org.testng.SuiteRunner.privateRun(SuiteRunner.java:415)
at org.testng.SuiteRunner.run(SuiteRunner.java:364)
at org.testng.SuiteRunnerWorker.runSuite(SuiteRunnerWorker.java:52)
at org.testng.SuiteRunnerWorker.run(SuiteRunnerWorker.java:84)
at org.testng.TestNG.runSuitesSequentially(TestNG.java:1208)
at org.testng.TestNG.runSuitesLocally(TestNG.java:1137)
at org.testng.TestNG.runSuites(TestNG.java:1049)
at org.testng.TestNG.run(TestNG.java:1017)
at org.testng.remote.AbstractRemoteTestNG.run(AbstractRemoteTestNG.java:114)
at org.testng.remote.RemoteTestNG.initAndRun(RemoteTestNG.java:251)
at org.testng.remote.RemoteTestNG.main(RemoteTestNG.java:77)
]]>
    </error>
  </testcase> <!-- verifyLogin -->
  <testcase name="logout" time="0.003" classname="jan23.WebdriverCross">
    <error type="java.lang.NullPointerException">
      <![CDATA[java.lang.NullPointerException
at jan23.WebdriverCross.logout(WebdriverCross.java:61)
at sun.reflect.NativeMethodAccessorImpl.invoke0(Native Method)
at sun.reflect.NativeMethodAccessorImpl.invoke(Unknown Source)
at sun.reflect.DelegatingMethodAccessorImpl.invoke(Unknown Source)
at java.lang.reflect.Method.invoke(Unknown Source)
at org.testng.internal.MethodInvocationHelper.invokeMethod(MethodInvocationHelper.java:124)
at org.testng.internal.MethodInvocationHelper.invokeMethodConsideringTimeout(MethodInvocationHelper.java:59)
at org.testng.internal.Invoker.invokeConfigurationMethod(Invoker.java:455)
at org.testng.internal.Invoker.invokeConfigurations(Invoker.java:222)
at org.testng.internal.Invoker.invokeConfigurations(Invoker.java:142)
at org.testng.TestRunner.afterRun(TestRunner.java:725)
at org.testng.TestRunner.run(TestRunner.java:509)
at org.testng.SuiteRunner.runTest(SuiteRunner.java:455)
at org.testng.SuiteRunner.runSequentially(SuiteRunner.java:450)
at org.testng.SuiteRunner.privateRun(SuiteRunner.java:415)
at org.testng.SuiteRunner.run(SuiteRunner.java:364)
at org.testng.SuiteRunnerWorker.runSuite(SuiteRunnerWorker.java:52)
at org.testng.SuiteRunnerWorker.run(SuiteRunnerWorker.java:84)
at org.testng.TestNG.runSuitesSequentially(TestNG.java:1208)
at org.testng.TestNG.runSuitesLocally(TestNG.java:1137)
at org.testng.TestNG.runSuites(TestNG.java:1049)
at org.testng.TestNG.run(TestNG.java:1017)
at org.testng.remote.AbstractRemoteTestNG.run(AbstractRemoteTestNG.java:114)
at org.testng.remote.RemoteTestNG.initAndRun(RemoteTestNG.java:251)
at org.testng.remote.RemoteTestNG.main(RemoteTestNG.java:77)
]]>
    </error>
  </testcase> <!-- logout -->
</testsuite> <!-- jan23.WebdriverCross -->
